[2025-04-06T19:15:29.746+0000] {taskinstance.py:1159} INFO - Dependencies all met for dep_context=non-requeueable deps ti=<TaskInstance: googlemaps_api.run_API_GM scheduled__2025-04-06T18:00:00+00:00 [queued]>
[2025-04-06T19:15:29.776+0000] {taskinstance.py:1159} INFO - Dependencies all met for dep_context=requeueable deps ti=<TaskInstance: googlemaps_api.run_API_GM scheduled__2025-04-06T18:00:00+00:00 [queued]>
[2025-04-06T19:15:29.777+0000] {taskinstance.py:1361} INFO - Starting attempt 1 of 2
[2025-04-06T19:15:29.818+0000] {taskinstance.py:1382} INFO - Executing <Task(PythonOperator): run_API_GM> on 2025-04-06 18:00:00+00:00
[2025-04-06T19:15:29.833+0000] {standard_task_runner.py:57} INFO - Started process 57 to run task
[2025-04-06T19:15:29.849+0000] {standard_task_runner.py:84} INFO - Running: ['***', 'tasks', 'run', 'googlemaps_api', 'run_API_GM', 'scheduled__2025-04-06T18:00:00+00:00', '--job-id', '6', '--raw', '--subdir', 'DAGS_FOLDER/dag_gm.py', '--cfg-path', '/tmp/tmpcy23tbav']
[2025-04-06T19:15:29.867+0000] {standard_task_runner.py:85} INFO - Job 6: Subtask run_API_GM
[2025-04-06T19:15:30.236+0000] {task_command.py:416} INFO - Running <TaskInstance: googlemaps_api.run_API_GM scheduled__2025-04-06T18:00:00+00:00 [running]> on host 9cf6fc43a3c9
[2025-04-06T19:15:30.787+0000] {taskinstance.py:1662} INFO - Exporting env vars: AIRFLOW_CTX_DAG_OWNER='***' AIRFLOW_CTX_DAG_ID='googlemaps_api' AIRFLOW_CTX_TASK_ID='run_API_GM' AIRFLOW_CTX_EXECUTION_DATE='2025-04-06T18:00:00+00:00' AIRFLOW_CTX_TRY_NUMBER='1' AIRFLOW_CTX_DAG_RUN_ID='scheduled__2025-04-06T18:00:00+00:00'
[2025-04-06T19:15:32.263+0000] {taskinstance.py:1937} ERROR - Task failed with exception
Traceback (most recent call last):
  File "/home/airflow/.local/lib/python3.8/site-packages/fsspec/registry.py", line 234, in get_filesystem_class
    register_implementation(protocol, _import_class(bit["class"]))
  File "/home/airflow/.local/lib/python3.8/site-packages/fsspec/registry.py", line 269, in _import_class
    mod = importlib.import_module(mod)
  File "/usr/local/lib/python3.8/importlib/__init__.py", line 127, in import_module
    return _bootstrap._gcd_import(name[level:], package, level)
  File "<frozen importlib._bootstrap>", line 1014, in _gcd_import
  File "<frozen importlib._bootstrap>", line 991, in _find_and_load
  File "<frozen importlib._bootstrap>", line 973, in _find_and_load_unlocked
ModuleNotFoundError: No module named 's3fs'

The above exception was the direct cause of the following exception:

Traceback (most recent call last):
  File "/home/airflow/.local/lib/python3.8/site-packages/airflow/operators/python.py", line 192, in execute
    return_value = self.execute_callable()
  File "/home/airflow/.local/lib/python3.8/site-packages/airflow/operators/python.py", line 209, in execute_callable
    return self.python_callable(*self.op_args, **self.op_kwargs)
  File "/opt/airflow/apis/API_GM.py", line 76, in main
    df = pd.read_csv(
  File "/home/airflow/.local/lib/python3.8/site-packages/pandas/io/parsers/readers.py", line 912, in read_csv
    return _read(filepath_or_buffer, kwds)
  File "/home/airflow/.local/lib/python3.8/site-packages/pandas/io/parsers/readers.py", line 577, in _read
    parser = TextFileReader(filepath_or_buffer, **kwds)
  File "/home/airflow/.local/lib/python3.8/site-packages/pandas/io/parsers/readers.py", line 1407, in __init__
    self._engine = self._make_engine(f, self.engine)
  File "/home/airflow/.local/lib/python3.8/site-packages/pandas/io/parsers/readers.py", line 1661, in _make_engine
    self.handles = get_handle(
  File "/home/airflow/.local/lib/python3.8/site-packages/pandas/io/common.py", line 716, in get_handle
    ioargs = _get_filepath_or_buffer(
  File "/home/airflow/.local/lib/python3.8/site-packages/pandas/io/common.py", line 414, in _get_filepath_or_buffer
    file_obj = fsspec.open(
  File "/home/airflow/.local/lib/python3.8/site-packages/fsspec/core.py", line 452, in open
    out = open_files(
  File "/home/airflow/.local/lib/python3.8/site-packages/fsspec/core.py", line 280, in open_files
    fs, fs_token, paths = get_fs_token_paths(
  File "/home/airflow/.local/lib/python3.8/site-packages/fsspec/core.py", line 610, in get_fs_token_paths
    chain = _un_chain(urlpath0, storage_options or {})
  File "/home/airflow/.local/lib/python3.8/site-packages/fsspec/core.py", line 325, in _un_chain
    cls = get_filesystem_class(protocol)
  File "/home/airflow/.local/lib/python3.8/site-packages/fsspec/registry.py", line 236, in get_filesystem_class
    raise ImportError(bit["err"]) from e
ImportError: Install s3fs to access S3
[2025-04-06T19:15:32.298+0000] {taskinstance.py:1400} INFO - Marking task as UP_FOR_RETRY. dag_id=googlemaps_api, task_id=run_API_GM, execution_date=20250406T180000, start_date=20250406T191529, end_date=20250406T191532
[2025-04-06T19:15:32.331+0000] {standard_task_runner.py:104} ERROR - Failed to execute job 6 for task run_API_GM (Install s3fs to access S3; 57)
[2025-04-06T19:15:32.410+0000] {local_task_job_runner.py:228} INFO - Task exited with return code 1
[2025-04-06T19:15:32.477+0000] {taskinstance.py:2778} INFO - 0 downstream tasks scheduled from follow-on schedule check
[2025-04-06T19:29:15.047+0000] {taskinstance.py:1159} INFO - Dependencies all met for dep_context=non-requeueable deps ti=<TaskInstance: googlemaps_api.run_API_GM scheduled__2025-04-06T18:00:00+00:00 [queued]>
[2025-04-06T19:29:15.120+0000] {taskinstance.py:1159} INFO - Dependencies all met for dep_context=requeueable deps ti=<TaskInstance: googlemaps_api.run_API_GM scheduled__2025-04-06T18:00:00+00:00 [queued]>
[2025-04-06T19:29:15.126+0000] {taskinstance.py:1361} INFO - Starting attempt 1 of 2
[2025-04-06T19:29:16.301+0000] {taskinstance.py:1382} INFO - Executing <Task(PythonOperator): run_API_GM> on 2025-04-06 18:00:00+00:00
[2025-04-06T19:29:16.325+0000] {standard_task_runner.py:57} INFO - Started process 50 to run task
[2025-04-06T19:29:16.335+0000] {standard_task_runner.py:84} INFO - Running: ['***', 'tasks', 'run', 'googlemaps_api', 'run_API_GM', 'scheduled__2025-04-06T18:00:00+00:00', '--job-id', '3', '--raw', '--subdir', 'DAGS_FOLDER/dag_gm.py', '--cfg-path', '/tmp/tmp_xt_9i6f']
[2025-04-06T19:29:16.360+0000] {standard_task_runner.py:85} INFO - Job 3: Subtask run_API_GM
[2025-04-06T19:29:16.529+0000] {task_command.py:416} INFO - Running <TaskInstance: googlemaps_api.run_API_GM scheduled__2025-04-06T18:00:00+00:00 [running]> on host abdb075469cd
[2025-04-06T19:29:16.854+0000] {taskinstance.py:1662} INFO - Exporting env vars: AIRFLOW_CTX_DAG_OWNER='***' AIRFLOW_CTX_DAG_ID='googlemaps_api' AIRFLOW_CTX_TASK_ID='run_API_GM' AIRFLOW_CTX_EXECUTION_DATE='2025-04-06T18:00:00+00:00' AIRFLOW_CTX_TRY_NUMBER='1' AIRFLOW_CTX_DAG_RUN_ID='scheduled__2025-04-06T18:00:00+00:00'
[2025-04-06T19:29:20.232+0000] {taskinstance.py:1937} ERROR - Task failed with exception
Traceback (most recent call last):
  File "/home/airflow/.local/lib/python3.8/site-packages/fsspec/registry.py", line 234, in get_filesystem_class
    register_implementation(protocol, _import_class(bit["class"]))
  File "/home/airflow/.local/lib/python3.8/site-packages/fsspec/registry.py", line 269, in _import_class
    mod = importlib.import_module(mod)
  File "/usr/local/lib/python3.8/importlib/__init__.py", line 127, in import_module
    return _bootstrap._gcd_import(name[level:], package, level)
  File "<frozen importlib._bootstrap>", line 1014, in _gcd_import
  File "<frozen importlib._bootstrap>", line 991, in _find_and_load
  File "<frozen importlib._bootstrap>", line 973, in _find_and_load_unlocked
ModuleNotFoundError: No module named 's3fs'

The above exception was the direct cause of the following exception:

Traceback (most recent call last):
  File "/home/airflow/.local/lib/python3.8/site-packages/airflow/operators/python.py", line 192, in execute
    return_value = self.execute_callable()
  File "/home/airflow/.local/lib/python3.8/site-packages/airflow/operators/python.py", line 209, in execute_callable
    return self.python_callable(*self.op_args, **self.op_kwargs)
  File "/opt/airflow/apis/API_GM.py", line 76, in main
    df = pd.read_csv(
  File "/home/airflow/.local/lib/python3.8/site-packages/pandas/io/parsers/readers.py", line 912, in read_csv
    return _read(filepath_or_buffer, kwds)
  File "/home/airflow/.local/lib/python3.8/site-packages/pandas/io/parsers/readers.py", line 577, in _read
    parser = TextFileReader(filepath_or_buffer, **kwds)
  File "/home/airflow/.local/lib/python3.8/site-packages/pandas/io/parsers/readers.py", line 1407, in __init__
    self._engine = self._make_engine(f, self.engine)
  File "/home/airflow/.local/lib/python3.8/site-packages/pandas/io/parsers/readers.py", line 1661, in _make_engine
    self.handles = get_handle(
  File "/home/airflow/.local/lib/python3.8/site-packages/pandas/io/common.py", line 716, in get_handle
    ioargs = _get_filepath_or_buffer(
  File "/home/airflow/.local/lib/python3.8/site-packages/pandas/io/common.py", line 414, in _get_filepath_or_buffer
    file_obj = fsspec.open(
  File "/home/airflow/.local/lib/python3.8/site-packages/fsspec/core.py", line 452, in open
    out = open_files(
  File "/home/airflow/.local/lib/python3.8/site-packages/fsspec/core.py", line 280, in open_files
    fs, fs_token, paths = get_fs_token_paths(
  File "/home/airflow/.local/lib/python3.8/site-packages/fsspec/core.py", line 610, in get_fs_token_paths
    chain = _un_chain(urlpath0, storage_options or {})
  File "/home/airflow/.local/lib/python3.8/site-packages/fsspec/core.py", line 325, in _un_chain
    cls = get_filesystem_class(protocol)
  File "/home/airflow/.local/lib/python3.8/site-packages/fsspec/registry.py", line 236, in get_filesystem_class
    raise ImportError(bit["err"]) from e
ImportError: Install s3fs to access S3
[2025-04-06T19:29:20.267+0000] {taskinstance.py:1400} INFO - Marking task as UP_FOR_RETRY. dag_id=googlemaps_api, task_id=run_API_GM, execution_date=20250406T180000, start_date=20250406T192915, end_date=20250406T192920
[2025-04-06T19:29:20.313+0000] {standard_task_runner.py:104} ERROR - Failed to execute job 3 for task run_API_GM (Install s3fs to access S3; 50)
[2025-04-06T19:29:20.351+0000] {local_task_job_runner.py:228} INFO - Task exited with return code 1
[2025-04-06T19:29:20.398+0000] {taskinstance.py:2778} INFO - 0 downstream tasks scheduled from follow-on schedule check
[2025-04-06T19:40:40.073+0000] {taskinstance.py:1159} INFO - Dependencies all met for dep_context=non-requeueable deps ti=<TaskInstance: googlemaps_api.run_API_GM scheduled__2025-04-06T18:00:00+00:00 [queued]>
[2025-04-06T19:40:40.099+0000] {taskinstance.py:1159} INFO - Dependencies all met for dep_context=requeueable deps ti=<TaskInstance: googlemaps_api.run_API_GM scheduled__2025-04-06T18:00:00+00:00 [queued]>
[2025-04-06T19:40:40.100+0000] {taskinstance.py:1361} INFO - Starting attempt 1 of 2
[2025-04-06T19:40:40.142+0000] {taskinstance.py:1382} INFO - Executing <Task(PythonOperator): run_API_GM> on 2025-04-06 18:00:00+00:00
[2025-04-06T19:40:40.164+0000] {standard_task_runner.py:57} INFO - Started process 46 to run task
[2025-04-06T19:40:40.176+0000] {standard_task_runner.py:84} INFO - Running: ['***', 'tasks', 'run', 'googlemaps_api', 'run_API_GM', 'scheduled__2025-04-06T18:00:00+00:00', '--job-id', '3', '--raw', '--subdir', 'DAGS_FOLDER/dag_gm.py', '--cfg-path', '/tmp/tmpvqc5bor6']
[2025-04-06T19:40:40.194+0000] {standard_task_runner.py:85} INFO - Job 3: Subtask run_API_GM
[2025-04-06T19:40:40.388+0000] {task_command.py:416} INFO - Running <TaskInstance: googlemaps_api.run_API_GM scheduled__2025-04-06T18:00:00+00:00 [running]> on host 615b20b05e08
[2025-04-06T19:40:41.322+0000] {taskinstance.py:1662} INFO - Exporting env vars: AIRFLOW_CTX_DAG_OWNER='***' AIRFLOW_CTX_DAG_ID='googlemaps_api' AIRFLOW_CTX_TASK_ID='run_API_GM' AIRFLOW_CTX_EXECUTION_DATE='2025-04-06T18:00:00+00:00' AIRFLOW_CTX_TRY_NUMBER='1' AIRFLOW_CTX_DAG_RUN_ID='scheduled__2025-04-06T18:00:00+00:00'
[2025-04-06T19:40:48.139+0000] {credentials.py:566} INFO - Found credentials in environment variables.
[2025-04-06T19:41:01.385+0000] {taskinstance.py:1937} ERROR - Task failed with exception
Traceback (most recent call last):
  File "/home/airflow/.local/lib/python3.8/site-packages/airflow/operators/python.py", line 192, in execute
    return_value = self.execute_callable()
  File "/home/airflow/.local/lib/python3.8/site-packages/airflow/operators/python.py", line 209, in execute_callable
    return self.python_callable(*self.op_args, **self.op_kwargs)
  File "/opt/airflow/apis/API_GM.py", line 83, in main
    review = get_restaurant_review(row.name)
  File "/opt/airflow/apis/API_GM.py", line 65, in get_restaurant_review
    return api.generate_multiple_reviews()
  File "/opt/airflow/apis/API_GM.py", line 41, in generate_multiple_reviews
    review = self.generate_review()
  File "/opt/airflow/apis/API_GM.py", line 30, in generate_review
    df = self.download_kaggle_csv_to_dataframe()
  File "/opt/airflow/apis/API_GM.py", line 24, in download_kaggle_csv_to_dataframe
    df = pd.read_csv(path, sep=',')
  File "/home/airflow/.local/lib/python3.8/site-packages/pandas/io/parsers/readers.py", line 912, in read_csv
    return _read(filepath_or_buffer, kwds)
  File "/home/airflow/.local/lib/python3.8/site-packages/pandas/io/parsers/readers.py", line 577, in _read
    parser = TextFileReader(filepath_or_buffer, **kwds)
  File "/home/airflow/.local/lib/python3.8/site-packages/pandas/io/parsers/readers.py", line 1407, in __init__
    self._engine = self._make_engine(f, self.engine)
  File "/home/airflow/.local/lib/python3.8/site-packages/pandas/io/parsers/readers.py", line 1661, in _make_engine
    self.handles = get_handle(
  File "/home/airflow/.local/lib/python3.8/site-packages/pandas/io/common.py", line 859, in get_handle
    handle = open(
FileNotFoundError: [Errno 2] No such file or directory: 'Restaurant_reviews.csv'
[2025-04-06T19:41:01.587+0000] {taskinstance.py:1400} INFO - Marking task as UP_FOR_RETRY. dag_id=googlemaps_api, task_id=run_API_GM, execution_date=20250406T180000, start_date=20250406T194040, end_date=20250406T194101
[2025-04-06T19:41:01.674+0000] {standard_task_runner.py:104} ERROR - Failed to execute job 3 for task run_API_GM ([Errno 2] No such file or directory: 'Restaurant_reviews.csv'; 46)
[2025-04-06T19:41:01.758+0000] {local_task_job_runner.py:228} INFO - Task exited with return code 1
[2025-04-06T19:41:01.825+0000] {taskinstance.py:2778} INFO - 0 downstream tasks scheduled from follow-on schedule check
[2025-04-06T19:56:24.613+0000] {taskinstance.py:1159} INFO - Dependencies all met for dep_context=non-requeueable deps ti=<TaskInstance: googlemaps_api.run_API_GM scheduled__2025-04-06T18:00:00+00:00 [queued]>
[2025-04-06T19:56:24.677+0000] {taskinstance.py:1159} INFO - Dependencies all met for dep_context=requeueable deps ti=<TaskInstance: googlemaps_api.run_API_GM scheduled__2025-04-06T18:00:00+00:00 [queued]>
[2025-04-06T19:56:24.678+0000] {taskinstance.py:1361} INFO - Starting attempt 1 of 2
[2025-04-06T19:56:24.776+0000] {taskinstance.py:1382} INFO - Executing <Task(PythonOperator): run_API_GM> on 2025-04-06 18:00:00+00:00
[2025-04-06T19:56:24.812+0000] {standard_task_runner.py:57} INFO - Started process 47 to run task
[2025-04-06T19:56:24.849+0000] {standard_task_runner.py:84} INFO - Running: ['***', 'tasks', 'run', 'googlemaps_api', 'run_API_GM', 'scheduled__2025-04-06T18:00:00+00:00', '--job-id', '3', '--raw', '--subdir', 'DAGS_FOLDER/dag_gm.py', '--cfg-path', '/tmp/tmpoeycci8h']
[2025-04-06T19:56:24.872+0000] {standard_task_runner.py:85} INFO - Job 3: Subtask run_API_GM
[2025-04-06T19:56:25.154+0000] {task_command.py:416} INFO - Running <TaskInstance: googlemaps_api.run_API_GM scheduled__2025-04-06T18:00:00+00:00 [running]> on host 4f8dac0cd162
[2025-04-06T19:56:25.374+0000] {taskinstance.py:1662} INFO - Exporting env vars: AIRFLOW_CTX_DAG_OWNER='***' AIRFLOW_CTX_DAG_ID='googlemaps_api' AIRFLOW_CTX_TASK_ID='run_API_GM' AIRFLOW_CTX_EXECUTION_DATE='2025-04-06T18:00:00+00:00' AIRFLOW_CTX_TRY_NUMBER='1' AIRFLOW_CTX_DAG_RUN_ID='scheduled__2025-04-06T18:00:00+00:00'
[2025-04-06T19:56:28.487+0000] {credentials.py:566} INFO - Found credentials in environment variables.
[2025-04-06T19:56:44.314+0000] {logging_mixin.py:151} INFO - [S3]Restaurant Restaurant Fil Manila uploaded correctly
[2025-04-06T19:56:48.883+0000] {logging_mixin.py:151} INFO - [S3]Restaurant Restaurant Japonès Kin Sushi Bar uploaded correctly
[2025-04-06T19:56:53.105+0000] {logging_mixin.py:151} INFO - [S3]Restaurant Bar Restaurant Amsterdam uploaded correctly
[2025-04-06T19:56:53.112+0000] {python.py:194} INFO - Done. Returned value was: None
[2025-04-06T19:56:53.148+0000] {taskinstance.py:1400} INFO - Marking task as SUCCESS. dag_id=googlemaps_api, task_id=run_API_GM, execution_date=20250406T180000, start_date=20250406T195624, end_date=20250406T195653
[2025-04-06T19:56:53.249+0000] {local_task_job_runner.py:228} INFO - Task exited with return code 0
[2025-04-06T19:56:53.322+0000] {taskinstance.py:2778} INFO - 0 downstream tasks scheduled from follow-on schedule check
