[2025-04-06T19:40:40.075+0000] {taskinstance.py:1159} INFO - Dependencies all met for dep_context=non-requeueable deps ti=<TaskInstance: googlemaps_api.run_API_GM manual__2025-04-06T19:40:21.692881+00:00 [queued]>
[2025-04-06T19:40:40.099+0000] {taskinstance.py:1159} INFO - Dependencies all met for dep_context=requeueable deps ti=<TaskInstance: googlemaps_api.run_API_GM manual__2025-04-06T19:40:21.692881+00:00 [queued]>
[2025-04-06T19:40:40.101+0000] {taskinstance.py:1361} INFO - Starting attempt 1 of 2
[2025-04-06T19:40:40.142+0000] {taskinstance.py:1382} INFO - Executing <Task(PythonOperator): run_API_GM> on 2025-04-06 19:40:21.692881+00:00
[2025-04-06T19:40:40.167+0000] {standard_task_runner.py:57} INFO - Started process 47 to run task
[2025-04-06T19:40:40.189+0000] {standard_task_runner.py:84} INFO - Running: ['***', 'tasks', 'run', 'googlemaps_api', 'run_API_GM', 'manual__2025-04-06T19:40:21.692881+00:00', '--job-id', '2', '--raw', '--subdir', 'DAGS_FOLDER/dag_gm.py', '--cfg-path', '/tmp/tmpz2wdclfr']
[2025-04-06T19:40:40.247+0000] {standard_task_runner.py:85} INFO - Job 2: Subtask run_API_GM
[2025-04-06T19:40:40.926+0000] {task_command.py:416} INFO - Running <TaskInstance: googlemaps_api.run_API_GM manual__2025-04-06T19:40:21.692881+00:00 [running]> on host 615b20b05e08
[2025-04-06T19:40:41.714+0000] {taskinstance.py:1662} INFO - Exporting env vars: AIRFLOW_CTX_DAG_OWNER='***' AIRFLOW_CTX_DAG_ID='googlemaps_api' AIRFLOW_CTX_TASK_ID='run_API_GM' AIRFLOW_CTX_EXECUTION_DATE='2025-04-06T19:40:21.692881+00:00' AIRFLOW_CTX_TRY_NUMBER='1' AIRFLOW_CTX_DAG_RUN_ID='manual__2025-04-06T19:40:21.692881+00:00'
[2025-04-06T19:40:48.143+0000] {credentials.py:566} INFO - Found credentials in environment variables.
[2025-04-06T19:41:00.529+0000] {taskinstance.py:1937} ERROR - Task failed with exception
Traceback (most recent call last):
  File "/home/airflow/.local/lib/python3.8/site-packages/airflow/operators/python.py", line 192, in execute
    return_value = self.execute_callable()
  File "/home/airflow/.local/lib/python3.8/site-packages/airflow/operators/python.py", line 209, in execute_callable
    return self.python_callable(*self.op_args, **self.op_kwargs)
  File "/opt/airflow/apis/API_GM.py", line 83, in main
    review = get_restaurant_review(row.name)
  File "/opt/airflow/apis/API_GM.py", line 65, in get_restaurant_review
    return api.generate_multiple_reviews()
  File "/opt/airflow/apis/API_GM.py", line 41, in generate_multiple_reviews
    review = self.generate_review()
  File "/opt/airflow/apis/API_GM.py", line 30, in generate_review
    df = self.download_kaggle_csv_to_dataframe()
  File "/opt/airflow/apis/API_GM.py", line 24, in download_kaggle_csv_to_dataframe
    df = pd.read_csv(path, sep=',')
  File "/home/airflow/.local/lib/python3.8/site-packages/pandas/io/parsers/readers.py", line 912, in read_csv
    return _read(filepath_or_buffer, kwds)
  File "/home/airflow/.local/lib/python3.8/site-packages/pandas/io/parsers/readers.py", line 577, in _read
    parser = TextFileReader(filepath_or_buffer, **kwds)
  File "/home/airflow/.local/lib/python3.8/site-packages/pandas/io/parsers/readers.py", line 1407, in __init__
    self._engine = self._make_engine(f, self.engine)
  File "/home/airflow/.local/lib/python3.8/site-packages/pandas/io/parsers/readers.py", line 1661, in _make_engine
    self.handles = get_handle(
  File "/home/airflow/.local/lib/python3.8/site-packages/pandas/io/common.py", line 859, in get_handle
    handle = open(
FileNotFoundError: [Errno 2] No such file or directory: 'Restaurant_reviews.csv'
[2025-04-06T19:41:00.608+0000] {taskinstance.py:1400} INFO - Marking task as UP_FOR_RETRY. dag_id=googlemaps_api, task_id=run_API_GM, execution_date=20250406T194021, start_date=20250406T194040, end_date=20250406T194100
[2025-04-06T19:41:00.684+0000] {standard_task_runner.py:104} ERROR - Failed to execute job 2 for task run_API_GM ([Errno 2] No such file or directory: 'Restaurant_reviews.csv'; 47)
[2025-04-06T19:41:00.810+0000] {local_task_job_runner.py:228} INFO - Task exited with return code 1
[2025-04-06T19:41:01.199+0000] {taskinstance.py:2778} INFO - 0 downstream tasks scheduled from follow-on schedule check
