[2025-04-06T18:17:40.030+0000] {taskinstance.py:1159} INFO - Dependencies all met for dep_context=non-requeueable deps ti=<TaskInstance: bcn_api.run_API_BCN manual__2025-04-06T18:17:19.903787+00:00 [queued]>
[2025-04-06T18:17:40.143+0000] {taskinstance.py:1159} INFO - Dependencies all met for dep_context=requeueable deps ti=<TaskInstance: bcn_api.run_API_BCN manual__2025-04-06T18:17:19.903787+00:00 [queued]>
[2025-04-06T18:17:40.144+0000] {taskinstance.py:1361} INFO - Starting attempt 1 of 2
[2025-04-06T18:17:40.203+0000] {taskinstance.py:1382} INFO - Executing <Task(PythonOperator): run_API_BCN> on 2025-04-06 18:17:19.903787+00:00
[2025-04-06T18:17:40.253+0000] {standard_task_runner.py:57} INFO - Started process 48 to run task
[2025-04-06T18:17:40.273+0000] {standard_task_runner.py:84} INFO - Running: ['***', 'tasks', 'run', 'bcn_api', 'run_API_BCN', 'manual__2025-04-06T18:17:19.903787+00:00', '--job-id', '2', '--raw', '--subdir', 'DAGS_FOLDER/dag_bcn.py', '--cfg-path', '/tmp/tmpv6o1rubv']
[2025-04-06T18:17:40.279+0000] {standard_task_runner.py:85} INFO - Job 2: Subtask run_API_BCN
[2025-04-06T18:17:40.669+0000] {task_command.py:416} INFO - Running <TaskInstance: bcn_api.run_API_BCN manual__2025-04-06T18:17:19.903787+00:00 [running]> on host 0fd160a17a3e
[2025-04-06T18:17:41.244+0000] {taskinstance.py:1662} INFO - Exporting env vars: AIRFLOW_CTX_DAG_OWNER='***' AIRFLOW_CTX_DAG_ID='bcn_api' AIRFLOW_CTX_TASK_ID='run_API_BCN' AIRFLOW_CTX_EXECUTION_DATE='2025-04-06T18:17:19.903787+00:00' AIRFLOW_CTX_TRY_NUMBER='1' AIRFLOW_CTX_DAG_RUN_ID='manual__2025-04-06T18:17:19.903787+00:00'
[2025-04-06T18:18:11.949+0000] {taskinstance.py:1937} ERROR - Task failed with exception
Traceback (most recent call last):
  File "/home/airflow/.local/lib/python3.8/site-packages/airflow/operators/python.py", line 192, in execute
    return_value = self.execute_callable()
  File "/home/airflow/.local/lib/python3.8/site-packages/airflow/operators/python.py", line 209, in execute_callable
    return self.python_callable(*self.op_args, **self.op_kwargs)
  File "/opt/airflow/apis/API_BCN.py", line 25, in main
    s3.put_object(
  File "/home/airflow/.local/lib/python3.8/site-packages/botocore/client.py", line 535, in _api_call
    return self._make_api_call(operation_name, kwargs)
  File "/home/airflow/.local/lib/python3.8/site-packages/botocore/client.py", line 963, in _make_api_call
    http, parsed_response = self._make_request(
  File "/home/airflow/.local/lib/python3.8/site-packages/botocore/client.py", line 986, in _make_request
    return self._endpoint.make_request(operation_model, request_dict)
  File "/home/airflow/.local/lib/python3.8/site-packages/botocore/endpoint.py", line 119, in make_request
    return self._send_request(request_dict, operation_model)
  File "/home/airflow/.local/lib/python3.8/site-packages/botocore/endpoint.py", line 198, in _send_request
    request = self.create_request(request_dict, operation_model)
  File "/home/airflow/.local/lib/python3.8/site-packages/botocore/endpoint.py", line 134, in create_request
    self._event_emitter.emit(
  File "/home/airflow/.local/lib/python3.8/site-packages/botocore/hooks.py", line 412, in emit
    return self._emitter.emit(aliased_event_name, **kwargs)
  File "/home/airflow/.local/lib/python3.8/site-packages/botocore/hooks.py", line 256, in emit
    return self._emit(event_name, kwargs)
  File "/home/airflow/.local/lib/python3.8/site-packages/botocore/hooks.py", line 239, in _emit
    response = handler(**kwargs)
  File "/home/airflow/.local/lib/python3.8/site-packages/botocore/signers.py", line 105, in handler
    return self.sign(operation_name, request)
  File "/home/airflow/.local/lib/python3.8/site-packages/botocore/signers.py", line 189, in sign
    auth.add_auth(request)
  File "/home/airflow/.local/lib/python3.8/site-packages/botocore/auth.py", line 418, in add_auth
    raise NoCredentialsError()
botocore.exceptions.NoCredentialsError: Unable to locate credentials
[2025-04-06T18:18:11.984+0000] {taskinstance.py:1400} INFO - Marking task as UP_FOR_RETRY. dag_id=bcn_api, task_id=run_API_BCN, execution_date=20250406T181719, start_date=20250406T181740, end_date=20250406T181811
[2025-04-06T18:18:12.021+0000] {standard_task_runner.py:104} ERROR - Failed to execute job 2 for task run_API_BCN (Unable to locate credentials; 48)
[2025-04-06T18:18:12.061+0000] {local_task_job_runner.py:228} INFO - Task exited with return code 1
[2025-04-06T18:18:12.097+0000] {taskinstance.py:2778} INFO - 0 downstream tasks scheduled from follow-on schedule check
