[2025-04-06T19:29:15.001+0000] {taskinstance.py:1159} INFO - Dependencies all met for dep_context=non-requeueable deps ti=<TaskInstance: googlemaps_api.run_API_GM manual__2025-04-06T19:28:50.434964+00:00 [queued]>
[2025-04-06T19:29:15.052+0000] {taskinstance.py:1159} INFO - Dependencies all met for dep_context=requeueable deps ti=<TaskInstance: googlemaps_api.run_API_GM manual__2025-04-06T19:28:50.434964+00:00 [queued]>
[2025-04-06T19:29:15.087+0000] {taskinstance.py:1361} INFO - Starting attempt 1 of 2
[2025-04-06T19:29:16.290+0000] {taskinstance.py:1382} INFO - Executing <Task(PythonOperator): run_API_GM> on 2025-04-06 19:28:50.434964+00:00
[2025-04-06T19:29:16.351+0000] {standard_task_runner.py:84} INFO - Running: ['***', 'tasks', 'run', 'googlemaps_api', 'run_API_GM', 'manual__2025-04-06T19:28:50.434964+00:00', '--job-id', '2', '--raw', '--subdir', 'DAGS_FOLDER/dag_gm.py', '--cfg-path', '/tmp/tmpw9882mqs']
[2025-04-06T19:29:16.352+0000] {standard_task_runner.py:57} INFO - Started process 51 to run task
[2025-04-06T19:29:16.360+0000] {standard_task_runner.py:85} INFO - Job 2: Subtask run_API_GM
[2025-04-06T19:29:16.562+0000] {task_command.py:416} INFO - Running <TaskInstance: googlemaps_api.run_API_GM manual__2025-04-06T19:28:50.434964+00:00 [running]> on host abdb075469cd
[2025-04-06T19:29:16.826+0000] {taskinstance.py:1662} INFO - Exporting env vars: AIRFLOW_CTX_DAG_OWNER='***' AIRFLOW_CTX_DAG_ID='googlemaps_api' AIRFLOW_CTX_TASK_ID='run_API_GM' AIRFLOW_CTX_EXECUTION_DATE='2025-04-06T19:28:50.434964+00:00' AIRFLOW_CTX_TRY_NUMBER='1' AIRFLOW_CTX_DAG_RUN_ID='manual__2025-04-06T19:28:50.434964+00:00'
[2025-04-06T19:29:20.231+0000] {taskinstance.py:1937} ERROR - Task failed with exception
Traceback (most recent call last):
  File "/home/airflow/.local/lib/python3.8/site-packages/fsspec/registry.py", line 234, in get_filesystem_class
    register_implementation(protocol, _import_class(bit["class"]))
  File "/home/airflow/.local/lib/python3.8/site-packages/fsspec/registry.py", line 269, in _import_class
    mod = importlib.import_module(mod)
  File "/usr/local/lib/python3.8/importlib/__init__.py", line 127, in import_module
    return _bootstrap._gcd_import(name[level:], package, level)
  File "<frozen importlib._bootstrap>", line 1014, in _gcd_import
  File "<frozen importlib._bootstrap>", line 991, in _find_and_load
  File "<frozen importlib._bootstrap>", line 973, in _find_and_load_unlocked
ModuleNotFoundError: No module named 's3fs'

The above exception was the direct cause of the following exception:

Traceback (most recent call last):
  File "/home/airflow/.local/lib/python3.8/site-packages/airflow/operators/python.py", line 192, in execute
    return_value = self.execute_callable()
  File "/home/airflow/.local/lib/python3.8/site-packages/airflow/operators/python.py", line 209, in execute_callable
    return self.python_callable(*self.op_args, **self.op_kwargs)
  File "/opt/airflow/apis/API_GM.py", line 76, in main
    df = pd.read_csv(
  File "/home/airflow/.local/lib/python3.8/site-packages/pandas/io/parsers/readers.py", line 912, in read_csv
    return _read(filepath_or_buffer, kwds)
  File "/home/airflow/.local/lib/python3.8/site-packages/pandas/io/parsers/readers.py", line 577, in _read
    parser = TextFileReader(filepath_or_buffer, **kwds)
  File "/home/airflow/.local/lib/python3.8/site-packages/pandas/io/parsers/readers.py", line 1407, in __init__
    self._engine = self._make_engine(f, self.engine)
  File "/home/airflow/.local/lib/python3.8/site-packages/pandas/io/parsers/readers.py", line 1661, in _make_engine
    self.handles = get_handle(
  File "/home/airflow/.local/lib/python3.8/site-packages/pandas/io/common.py", line 716, in get_handle
    ioargs = _get_filepath_or_buffer(
  File "/home/airflow/.local/lib/python3.8/site-packages/pandas/io/common.py", line 414, in _get_filepath_or_buffer
    file_obj = fsspec.open(
  File "/home/airflow/.local/lib/python3.8/site-packages/fsspec/core.py", line 452, in open
    out = open_files(
  File "/home/airflow/.local/lib/python3.8/site-packages/fsspec/core.py", line 280, in open_files
    fs, fs_token, paths = get_fs_token_paths(
  File "/home/airflow/.local/lib/python3.8/site-packages/fsspec/core.py", line 610, in get_fs_token_paths
    chain = _un_chain(urlpath0, storage_options or {})
  File "/home/airflow/.local/lib/python3.8/site-packages/fsspec/core.py", line 325, in _un_chain
    cls = get_filesystem_class(protocol)
  File "/home/airflow/.local/lib/python3.8/site-packages/fsspec/registry.py", line 236, in get_filesystem_class
    raise ImportError(bit["err"]) from e
ImportError: Install s3fs to access S3
[2025-04-06T19:29:20.267+0000] {taskinstance.py:1400} INFO - Marking task as UP_FOR_RETRY. dag_id=googlemaps_api, task_id=run_API_GM, execution_date=20250406T192850, start_date=20250406T192915, end_date=20250406T192920
[2025-04-06T19:29:20.311+0000] {standard_task_runner.py:104} ERROR - Failed to execute job 2 for task run_API_GM (Install s3fs to access S3; 51)
[2025-04-06T19:29:20.360+0000] {local_task_job_runner.py:228} INFO - Task exited with return code 1
[2025-04-06T19:29:20.410+0000] {taskinstance.py:2778} INFO - 0 downstream tasks scheduled from follow-on schedule check
